Workbook

Sheet COVER
B8: Adobe Inc.
B10: October 2026
B25: Name
B26: Note: This model is created strictly for educational and portfolio demonstration purposes. It does not constitute investment advice or an offer to buy/sell any financial instruments.

Sheet Summary
B2: =COVER!B8 -> Adobe Inc.
B3: Revenue Schedule
C6: Summary - Base Case
K7: Projected
F9: =G9-1 -> 2021 | G9: =H9-1 -> 2022 | H9: =I9-1 -> 2023 | I9: =J9-1 -> 2024 | J9: =K9-1 -> 2025 | K9: =Assumptions!$G$4 -> 2026 | L9: =K9+1 -> 2027 | M9: =L9+1 -> 2028 | N9: =M9+1 -> 2029 | O9: =N9+1 -> 2030
C11: Net Revenue | F11: 15785 | G11: 17606 | H11: 19409 | I11: 21505 | J11: 23769 | K11: 26295 | L11: 28946 | M11: 31723 | N11: 34634 | O11: 37790
D12: YoY Growth | G12: 0.1154 | H12: 0.1024 | I12: 0.108 | J12: 0.1053 | K12: 0.1063 | L12: 0.1008 | M12: 0.0959 | N12: 0.0918 | O12: 0.0911
C13: Net Income | F13: 4822 | G13: 4756 | H13: 5428 | I13: 5560 | J13: 7130 | K13: 7120 | L13: 7923 | M13: 8769 | N13: 9646 | O13: 10577
D14: YoY Growth | G14: -0.0137 | H14: 0.1413 | I14: 0.0243 | J14: 0.2824 | K14: -0.0014 | L14: 0.1128 | M14: 0.1068 | N14: 0.1001 | O14: 0.0965
C15: Total ARR | I15: 22601 | J15: 25200 | K15: 27782 | L15: 30591 | M15: 33533 | N15: 36615 | O15: 39954
D16: YoY Growth | J16: 0.115 | K16: 0.1025 | L16: 0.1011 | M16: 0.0962 | N16: 0.0919 | O16: 0.0912 | T16: ="CURRENTLY RUNNING: "&UPPER(CHOOSE(Scenarios!$E$5,Scenarios!$D$11,Scenarios!$D$12,Scenarios!$D$13))&" SCENARIO" -> CURRENTLY RUNNING: BASE CASE SCENARIO
C17: EBT Margin | F17: 0.3676 | G17: 0.3464 | H17: 0.3426 | I17: 0.3135 | J17: 0.3663 | K17: 0.3452 | L17: 0.3468 | M17: 0.3482 | N17: 0.3483 | O17: 0.3483 | T17: Summary Values
C18: Return on Equity | F18: 0.3259 | G18: 0.3385 | H18: 0.3286 | I18: 0.3942 | J18: 0.6134 | K18: 0.5501 | L18: 0.5266 | M18: 0.4854 | N18: 0.4396 | O18: 0.3944 | AB18: Projected
C20: Implied Share Price | F20: 244.55 | W20: =X20-1 -> 2021 | X20: =Y20-1 -> 2022 | Y20: =Z20-1 -> 2023 | Z20: =AA20-1 -> 2024 | AA20: =AB20-1 -> 2025 | AB20: =Assumptions!$G$4 -> 2026 | AC20: =AB20+1 -> 2027 | AD20: =AC20+1 -> 2028 | AE20: =AD20+1 -> 2029 | AF20: =AE20+1 -> 2030
T22: Net Revenue | W22: =Model!H79 -> 15785 | X22: =Model!I79 -> 17606 | Y22: =Model!J79 -> 19409 | Z22: =Model!K79 -> 21505 | AA22: =Model!L79 -> 23769 | AB22: =Model!M79 -> 26294.531 | AC22: =Model!N79 -> 28946.097 | AD22: =Model!O79 -> 31723.046 | ... AF22: =Model!Q79 -> 37789.849
C23: Summary - Best Case | U23: YoY Growth | X23: =(X22-W22)/W22 -> 0.11536269 | Y23: =(Y22-X22)/X22 -> 0.10240827 | Z23: =(Z22-Y22)/Y22 -> 0.10799114 | AA23: =(AA22-Z22)/Z22 -> 0.10527784 | AB23: =(AB22-AA22)/AA22 -> 0.10625316 | AC23: =(AC22-AB22)/AB22 -> 0.10084095 | AD23: =(AD22-AC22)/AC22 -> 0.095935195 | AE23: =(AE22-AD22)/AD22 -> 0.091759504 | AF23: =(AF22-AE22)/AE22 -> 0.091121948
K24: Projected | T24: Net Income | W24: =Model!H94 -> 4822 | X24: =Model!I94 -> 4756 | Y24: =Model!J94 -> 5428 | Z24: =Model!K94 -> 5560 | AA24: =Model!L94 -> 7130 | AB24: =Model!M94 -> 7120.1094 | AC24: =Model!N94 -> 7923.0413 | AD24: =Model!O94 -> 8769.0078 | ... AF24: =Model!Q94 -> 10576.86
U25: YoY Growth | X25: =Model!I95 -> -0.013687267 | Y25: =Model!J95 -> 0.14129521 | Z25: =Model!K95 -> 0.024318349 | AA25: =Model!L95 -> 0.2823741 | AB25: =Model!M95 -> -0.0013871798 | AC25: =Model!N95 -> 0.1127696 | AD25: =Model!O95 -> 0.10677295 | AE25: =Model!P95 -> 0.10005324 | AF25: =Model!Q95 -> 0.096459506
F26: =G26-1 -> 2021 | G26: =H26-1 -> 2022 | H26: =I26-1 -> 2023 | I26: =J26-1 -> 2024 | J26: =K26-1 -> 2025 | K26: =Assumptions!$G$4 -> 2026 | L26: =K26+1 -> 2027 | M26: =L26+1 -> 2028 | N26: =M26+1 -> 2029 | O26: =N26+1 -> 2030 | T26: Total ARR | Z26: =Model!K32 -> 22600.897 | AA26: =Model!L32 -> 25200 | AB26: =Model!M32 -> 27781.989 | AC26: =Model!N32 -> 30591.325 | AD26: =Model!O32 -> 33533.124 | AE26: =Model!P32 -> 36614.513 | AF26: =Model!Q32 -> 39954.045
U27: YoY Growth | AA27: =Model!L33 -> 0.115 | AB27: =Model!M33 -> 0.10245989 | AC27: =Model!N33 -> 0.10112074 | AD27: =Model!O33 -> 0.096164496 | AE27: =Model!P33 -> 0.091890901 | AF27: =Model!Q33 -> 0.091207871
C28: Net Revenue | F28: 15785 | G28: 17606 | H28: 19409 | I28: 21505 | J28: 23769 | K28: 26447 | L28: 29152 | M28: 32095 | N28: 35247 | O28: 38710 | T28: EBT Margin | W28: =Model!H98 -> 0.36756414 | X28: =Model!I98 -> 0.3463592 | Y28: =Model!J98 -> 0.34262456 | Z28: =Model!K98 -> 0.31346199 | AA28: =Model!L98 -> 0.3662754 | AB28: =Model!M98 -> 0.34516998 | AC28: =Model!N98 -> 0.34676766 | AD28: =Model!O98 -> 0.34823792 | ... AF28: =Model!Q98 -> 0.34831582
D29: YoY Growth | G29: 0.1154 | H29: 0.1024 | I29: 0.108 | J29: 0.1053 | K29: 0.1127 | L29: 0.1023 | M29: 0.101 | N29: 0.0982 | O29: 0.0983 | T29: Return on Equity | W29: =Model!H99 -> 0.32587687 | X29: =Model!I99 -> 0.33848125 | Y29: =Model!J99 -> 0.32861121 | Z29: =Model!K99 -> 0.39418646 | AA29: =Model!L99 -> 0.61343887 | AB29: =Model!M99 -> 0.55010811 | AC29: =Model!N99 -> 0.52658261 | AD29: =Model!O99 -> 0.48540996 | ... AF29: =Model!Q99 -> 0.39438827
C30: Net Income | F30: 4822 | G30: 4756 | H30: 5428 | I30: 5560 | J30: 7130 | K30: 7163 | L30: 7982 | M30: 8875 | N30: 9821 | O30: 10840
D31: YoY Growth | G31: -0.0137 | H31: 0.1413 | I31: 0.0243 | J31: 0.2824 | K31: 0.0046 | L31: 0.1143 | M31: 0.1119 | N31: 0.1066 | O31: 0.1037 | T31: Implied Share Price | W31: =DCF!E23 -> 244.55377
C32: Total ARR | I32: 22601 | J32: 25200 | K32: 27944 | L32: 30809 | M32: 33927 | N32: 37264 | O32: 40929
D33: YoY Growth | J33: 0.115 | K33: 0.1089 | L33: 0.1025 | M33: 0.1012 | N33: 0.0983 | O33: 0.0984
C34: EBT Margin | F34: 0.3676 | G34: 0.3464 | H34: 0.3426 | I34: 0.3135 | J34: 0.3663 | K34: 0.3452 | L34: 0.3468 | M34: 0.3483 | N34: 0.3483 | O34: 0.3484
C35: Return on Equity | F35: 0.3259 | G35: 0.3385 | H35: 0.3286 | I35: 0.3942 | J35: 0.6134 | K35: 0.5516 | L35: 0.5269 | M35: 0.4857 | N35: 0.4399 | O35: 0.3947
C37: Implied Share Price | F37: 246.33
C40: Summary - Worst Case
K41: Projected
F43: =G43-1 -> 2021 | G43: =H43-1 -> 2022 | H43: =I43-1 -> 2023 | I43: =J43-1 -> 2024 | J43: =K43-1 -> 2025 | K43: =Assumptions!$G$4 -> 2026 | L43: =K43+1 -> 2027 | M43: =L43+1 -> 2028 | N43: =M43+1 -> 2029 | O43: =N43+1 -> 2030
C45: Net Revenue | F45: 15785 | G45: 17606 | H45: 19409 | I45: 21505 | J45: 23769 | K45: 26057 | L45: 28277 | M45: 30526 | N45: 32849 | O45: 35140
D46: YoY Growth | G46: 0.1154 | H46: 0.1024 | I46: 0.108 | J46: 0.1053 | K46: 0.0963 | L46: 0.0852 | M46: 0.0795 | N46: 0.0761 | O46: 0.0697
C47: Net Income | F47: 4822 | G47: 4756 | H47: 5428 | I47: 5560 | J47: 7130 | K47: 7053 | L47: 7734 | M47: 8429 | N47: 9137 | O47: 9819
D48: YoY Growth | G48: -0.0137 | H48: 0.1413 | I48: 0.0243 | J48: 0.2824 | K48: -0.0108 | L48: 0.0965 | M48: 0.0899 | N48: 0.084 | O48: 0.0746
C49: Total ARR | I49: 22601 | J49: 25200 | K49: 27531 | L49: 29885 | M49: 32269 | N49: 34729 | O49: 37154
D50: YoY Growth | J50: 0.115 | K50: 0.0925 | L50: 0.0855 | M50: 0.0798 | N50: 0.0762 | O50: 0.0698
C51: EBT Margin | F51: 0.3676 | G51: 0.3464 | H51: 0.3426 | I51: 0.3135 | J51: 0.3663 | K51: 0.3451 | L51: 0.3466 | M51: 0.3481 | N51: 0.3481 | O51: 0.3481
C52: Return on Equity | F52: 0.3259 | G52: 0.3385 | H52: 0.3286 | I52: 0.3942 | J52: 0.6134 | K52: 0.5478 | L52: 0.5229 | M52: 0.4825 | N52: 0.4385 | O52: 0.3935
...

Sheet Assumptions
B4: First year of forcast in financial model | G4: 2026 | I4: Digital Media, % of Total Revenue | M4: 0.735 | O4: Year-by-Year Assumptions | Q4: ($ MM) | R4: =$G$4 -> 2026 | S4: =R4+1 -> 2027 | T4: =S4+1 -> 2028 | U4: =T4+1 -> 2029 | V4: =U4+1 -> 2030
B5: Effective Corporate Tax Rate | G5: 0.2 | O5: Publishing and Advertising Revenue | R5: 250 | S5: 220 | T5: 100 | U5: 180 | V5: 160
B6: Total Subscription Revenue, % of Total Revenue | G6: 0.96 | O6: Publishing and Advertising Subscription | R6: 100 | S6: 95 | T6: 90 | U6: 87 | V6: 85
O7: Amortization to Existing Intangibles | R7: 161 | S7: 119 | T7: 73 | U7: 69 | V7: 65
B8: Cost & Expense of Revenue, % of Total Revenue | I8: Working Capital Items | O8: Amortization to Newly Purchased Intangibles | R8: =$G$19/$G$20*((R4+1)-$G$4) -> 13.333333 | S8: =$G$19/$G$20*((S4+1)-$G$4) -> 26.666667 | T8: =$G$19/$G$20*((T4+1)-$G$4) -> 40 | U8: =$G$19/$G$20*((U4+1)-$G$4) -> 53.333333 | V8: =$G$19/$G$20*((V4+1)-$G$4) -> 66.666667
B9: Subscription | G9: 0.088 | I9: Days in | O9: Repayment of Debt | R9: 0 | S9: =850+500 -> 1350 | T9: 800 | U9: 750 | V9: =700+1300 -> 2000
B10: Product | G10: 0.0012 | I10: Accounts Receivable | M10: 43 | O10: Stock-Based Compensation | R10: 2000 | S10: 2000 | T10: 2100 | U10: 2100 | V10: 2200
B11: Services and Other | G11: 0.025 | I11: Accounts Payable | M11: 60 | O11: Other Deperciation, Amortization and Accretion | R11: 400 | S11: 380 | T11: 350 | U11: 330 | V11: 300
B12: Research and Development | G12: 0.19 | I12: Prepaid Expenses, % of Operating Ex | M12: 0.1
B13: Sales and Marketing | G13: 0.275 | I13: Deferred Revenue, % of Revenue | M13: 0.298
B14: General and Administrative | G14: 0.069 | I14: Accrued Expenses, % of Operating Ex | M14: 0.198
B16: Depreciation and Amortization | I16: Debt and Interest
B17: Purchases, PP&E | F17: ($ MM) | G17: 200 | I17: Effective interest Rate (Cash) | M17: 0.01
B18: Depreciation, % of PP&E | G18: 0.122 | I18: Effective interest Rate (Debt) | M18: 0.0416
B19: Purchases, Other Intangibles | F19: ($ MM) | G19: 80 | I19: Issuance of Short-Term Debt | K19: ($ MM) | M19: 0
B20: Amortization Years of Other Intangibles | G20: 6 | I20: Issuance of Long-Term Debt | K20: ($ MM) | M20: 0
B21: Acquisitions | F21: ($ MM) | G21: 0
B23: Income Taxes | I23: Other Assumptions | M23: ($ MM)
B24: Deferred Income Tax, % of EBT | G24: 0.05 | I24: Changes in ROU Assets | M24: 0
B25: Changes in Income Taxes Payable | F25: ($ MM) | G25: 0 | I25: Adjustments in Common Stock | M25: -200
I26: Changes in Short-term Investments | M26: 0
B27: Non-Operating Adjustments | G27: ($ MM) | I27: Repurchase of Common Stock | M27: -8000
B28: Investment Gains (Losses) | G28: 0
B29: Other Income (Expense) | G29: 0

Sheet Model
Q1: ="CURRENTLY RUNNING: "&UPPER(CHOOSE(Scenarios!$E$5,Scenarios!$D$11,Scenarios!$D$12,Scenarios!$D$13))&" SCENARIO" -> CURRENTLY RUNNING: BASE CASE SCENARIO
B2: =COVER!B8 -> Adobe Inc.
B3: Revenue Schedule
M5: Projected
H7: =I7-1 -> 2021 | I7: =J7-1 -> 2022 | J7: =K7-1 -> 2023 | K7: =L7-1 -> 2024 | L7: =M7-1 -> 2025 | M7: =Assumptions!G4 -> 2026 | N7: =M7+1 -> 2027 | O7: =N7+1 -> 2028 | P7: =O7+1 -> 2029 | Q7: =P7+1 -> 2030
B9: Revenue, by Segment | F9: ($ MM)
C10: Digital Media | H10: 11520 | I10: 12842 | J10: 14216 | K10: 15864 | L10: 17649 | M10: =M15*Assumptions!$M$4 -> 19326.48 | N10: =N15*Assumptions!$M$4 -> 21275.381 | O10: =O15*Assumptions!$M$4 -> 23316.439 | P10: =P15*Assumptions!$M$4 -> 25455.944 | Q10: =Q15*Assumptions!$M$4 -> 27775.539
D11: YoY Growth | I11: =(I10-H10)/H10 -> 0.11475694 | J11: =(J10-I10)/I10 -> 0.10699268 | K11: =(K10-J10)/J10 -> 0.11592572 | L11: =(L10-K10)/K10 -> 0.11251891 | M11: =(M10-L10)/L10 -> 0.095046771 | N11: =(N10-M10)/M10 -> 0.10084095 | O11: =(O10-N10)/N10 -> 0.095935195 | P11: =(P10-O10)/O10 -> 0.091759504 | Q11: =(Q10-P10)/P10 -> 0.091121948
C12: Digital Experience | H12: 3867 | I12: 4422 | J12: 4893 | K12: 5366 | L12: 5864 | M12: =M15-M14-M10 -> 6718.0508 | N12: =N15-N14-N10 -> 7450.7156 | O12: =O15-O14-O10 -> 8306.6072 | P12: =P15-P14-P10 -> 8997.9934 | Q12: =Q15-Q14-Q10 -> 9854.31
D13: YoY Growth | I13: =(I12-H12)/H12 -> 0.14352211 | J13: =(J12-I12)/I12 -> 0.10651289 | K13: =(K12-J12)/J12 -> 0.09666871 | L13: =(L12-K12)/K12 -> 0.09280656 | M13: =(M12-L12)/L12 -> 0.14564304 | N13: =(N12-M12)/M12 -> 0.10905914 | O13: =(O12-N12)/N12 -> 0.11487374 | P13: =(P12-O12)/O12 -> 0.083233273 | Q13: =(Q12-P12)/P12 -> 0.095167512
C14: Publishing and Advertising | H14: 398 | I14: 342 | J14: 300 | K14: 275 | L14: 256 | M14: =Assumptions!R5 -> 250 | N14: =Assumptions!S5 -> 220 | O14: =Assumptions!T5 -> 100 | P14: =Assumptions!U5 -> 180 | Q14: =Assumptions!V5 -> 160
B15: Total Revenue | F15: ($ MM) | H15: =H14+H12+H10 -> 15785 | I15: =I14+I12+I10 -> 17606 | J15: =J14+J12+J10 -> 19409 | K15: =K14+K12+K10 -> 21505 | L15: =L14+L12+L10 -> 23769 | M15: =M26/M27 -> 26294.531 | N15: =N26/N27 -> 28946.097 | O15: =O26/O27 -> 31723.046 | P15: =P26/P27 -> 34633.937 | Q15: =Q26/Q27 -> 37789.849
D16: YoY Growth | I16: =(I15-H15)/H15 -> 0.11536269 | J16: =(J15-I15)/I15 -> 0.10240827 | K16: =(K15-J15)/J15 -> 0.10799114 | L16: =(L15-K15)/K15 -> 0.10527784 | M16: =(M15-L15)/L15 -> 0.10625316 | N16: =(N15-M15)/M15 -> 0.10084095 | O16: =(O15-N15)/N15 -> 0.095935195 | P16: =(P15-O15)/O15 -> 0.091759504 | Q16: =(Q15-P15)/P15 -> 0.091121948
B18: Subscription Revenue | F18: ($ MM)
C19: Creative & Marketing Professionals, DM & DX | J19: 13425 | K19: 14749 | L19: 16303 | M19: =L19*(1+M20) -> 17933.3 | N19: =M19*(1+N20) -> 19690.763 | O19: =N19*(1+O20) -> 21561.386 | P19: =O19*(1+P20) -> 23566.595 | Q19: =P19*(1+Q20) -> 25734.722
D20: YoY Growth | K20: =(K19-J19)/J19 -> 0.098621974 | L20: =(L19-K19)/K19 -> 0.10536308 | M20: =Scenarios!I9 -> 0.1 | N20: =Scenarios!J9 -> 0.098 | O20: =Scenarios!K9 -> 0.095 | P20: =Scenarios!L9 -> 0.093 | Q20: =Scenarios!M9 -> 0.092
D21: % of Subscription Revenue | K21: =K19/K26 -> 0.71872716 | L21: =L19/L26 -> 0.71179707 | M21: =M19/M26 -> 0.71043369 | N21: =N19/N26 -> 0.70860027 | O21: =O19/O26 -> 0.7079956 | P21: =P19/P26 -> 0.70880005 | Q21: =Q19/Q26 -> 0.70937043
C22: Business Professionals & Consumers, DM&DX | J22: 4744 | K22: 5662 | L22: 6495 | M22: =L22*(1+M23) -> 7209.45 | N22: =M22*(1+N23) -> 8002.4895 | O22: =N22*(1+O23) -> 8802.7385 | P22: =O22*(1+P23) -> 9594.9849 | Q22: =P22*(1+Q23) -> 10458.534
D23: YoY Growth | K23: =(K22-J22)/J22 -> 0.19350759 | L23: =(L22-K22)/K22 -> 0.14712116 | M23: =Scenarios!I15 -> 0.11 | N23: =Scenarios!J15 -> 0.11 | O23: =Scenarios!K15 -> 0.1 | P23: =Scenarios!L15 -> 0.09 | Q23: =Scenarios!M15 -> 0.09
D24: % of Subscription Revenue | K24: =K22/K26 -> 0.27591248 | L24: =L22/L26 -> 0.28357492 | M24: =M22/M26 -> 0.28560478 | N24: =N22/N26 -> 0.28798102 | O24: =O22/O26 -> 0.28904914 | P24: =P22/P26 -> 0.2885833 | Q24: =Q22/Q26 -> 0.28828657
C25: Publishing and Advertising | H25: 146 | I25: 123 | J25: 115 | K25: 110 | L25: 106 | M25: =Assumptions!R6 -> 100 | N25: =Assumptions!S6 -> 95 | O25: =Assumptions!T6 -> 90 | P25: =Assumptions!U6 -> 87 | Q25: =Assumptions!V6 -> 85
B26: Total Subscription Revenue | F26: ($ MM) | J26: =J25+J22+J19 -> 18284 | K26: =K25+K22+K19 -> 20521 | L26: =L25+L22+L19 -> 22904 | M26: =M25+M22+M19 -> 25242.75 | N26: =N25+N22+N19 -> 27788.253 | O26: =O25+O22+O19 -> 30454.124 | P26: =P25+P22+P19 -> 33248.58 | Q26: =Q25+Q22+Q19 -> 36278.255
C27: % of Total Revenue | J27: =J26/J15 -> 0.9420372 | K27: =K26/K15 -> 0.9542432 | L27: =L26/L15 -> 0.96360806 | M27: =Assumptions!$G$6 -> 0.96 | N27: =Assumptions!$G$6 -> 0.96 | O27: =Assumptions!$G$6 -> 0.96 | P27: =Assumptions!$G$6 -> 0.96 | Q27: =Assumptions!$G$6 -> 0.96
D28: YoY Growth | K28: =(K26-J26)/J26 -> 0.12234741 | L28: =(L26-K26)/K26 -> 0.11612495 | M28: =(M26-L26)/L26 -> 0.10211098 | N28: =(N26-M26)/M26 -> 0.10084095 | O28: =(O26-N26)/N26 -> 0.095935195 | P28: =(P26-O26)/O26 -> 0.091759504 | Q28: =(Q26-P26)/P26 -> 0.091121948
B30: Beginning Total ARR | F30: ($ MM) | L30: =K32 -> 22600.897 | M30: =L32 -> 25200 | N30: =M32 -> 27781.989 | O30: =N32 -> 30591.325 | P30: =O32 -> 33533.124 | Q30: =P32 -> 36614.513
B31: Add: Net New ARR | L31: =L32-L30 -> 2599.1031 | M31: =M30*M20*M21+M30*M23*M24 -> 2581.9893 | N31: =N30*N20*N21+N30*N23*N24 -> 2809.3353 | O31: =O30*O20*O21+O30*O23*O24 -> 2941.7993 | P31: =P30*P20*P21+P30*P23*P24 -> 3081.389 | Q31: =Q30*Q20*Q21+Q30*Q23*Q24 -> 3339.5318
B32: Ending Total ARR | F32: ($ MM) | K32: =L32/(1+11.5%) -> 22600.897 | L32: 25200 | M32: =M30+M31 -> 27781.989 | N32: =N30+N31 -> 30591.325 | O32: =O30+O31 -> 33533.124 | P32: =P30+P31 -> 36614.513 | Q32: =Q30+Q31 -> 39954.045
C33: YoY Growth | L33: =L31/L30 -> 0.115 | M33: =M31/M30 -> 0.10245989 | N33: =N31/N30 -> 0.10112074 | O33: =O31/O30 -> 0.096164496 | P33: =P31/P30 -> 0.091890901 | Q33: =Q31/Q30 -> 0.091207871
Q39: =$Q$1 -> CURRENTLY RUNNING: BASE CASE SCENARIO
B40: =$B$2 -> Adobe Inc.
B41: Cost and Expense Schedule
M43: Projected
H45: =I45-1 -> 2021 | I45: =J45-1 -> 2022 | J45: =K45-1 -> 2023 | K45: =L45-1 -> 2024 | L45: =M45-1 -> 2025 | M45: =$M$7 -> 2026 | N45: =M45+1 -> 2027 | O45: =N45+1 -> 2028 | P45: =O45+1 -> 2029 | Q45: =P45+1 -> 2030
B47: Cost of Revenue
C48: Subscription | H48: 1374 | I48: 1646 | J48: 1822 | K48: 1799 | L48: 2027 | M48: =M49*M15 -> 2313.9188 | N48: =N49*N15 -> 2547.2565 | O48: =O49*O15 -> 2791.6281 | P48: =P49*P15 -> 3047.7865 | Q48: =Q49*Q15 -> 3325.5067
D49: % of Total Revenue | H49: =H48/H15 -> 0.087044663 | I49: =I48/I15 -> 0.093490855 | J49: =J48/J15 -> 0.093873976 | K49: =K48/K15 -> 0.083654964 | L49: =L48/L15 -> 0.085279145 | M49: =Assumptions!$G$9 -> 0.088 | N49: =Assumptions!$G$9 -> 0.088 | O49: =Assumptions!$G$9 -> 0.088 | P49: =Assumptions!$G$9 -> 0.088 | Q49: =Assumptions!$G$9 -> 0.088
C50: Product | H50: 41 | I50: 35 | J50: 29 | K50: 25 | L50: 23 | M50: =M51*M15 -> 31.553438 | N50: =N51*N15 -> 34.735316 | O50: =O51*O15 -> 38.067655 | P50: =P51*P15 -> 41.560725 | Q50: =Q51*Q15 -> 45.347819
D51: % of Total Revenue | H51: =H50/H15 -> 0.0025974026 | I51: =I50/I15 -> 0.0019879587 | J51: =J50/J15 -> 0.0014941522 | K51: =K50/K15 -> 0.0011625203 | L51: =L50/L15 -> 0.00096764694 | M51: =Assumptions!$G$10 -> 0.0012 | N51: =Assumptions!$G$10 -> 0.0012 | O51: =Assumptions!$G$10 -> 0.0012 | P51: =Assumptions!$G$10 -> 0.0012 | Q51: =Assumptions!$G$10 -> 0.0012
C52: Services and Other | H52: 450 | I52: 484 | J52: 503 | K52: 534 | L52: 501 | M52: =M53*M15 -> 657.36328 | N52: =N53*N15 -> 723.65242 | O52: =O53*O15 -> 793.07616 | P52: =P53*P15 -> 865.84843 | Q52: =Q53*Q15 -> 944.74623
D53: % of Total Revenue | H53: =H52/H15 -> 0.028508077 | I53: =I52/I15 -> 0.027490628 | J53: =J52/J15 -> 0.025915812 | K53: =K52/K15 -> 0.024831435 | L53: =L52/L15 -> 0.021077875 | M53: =Assumptions!$G$11 -> 0.025 | N53: =Assumptions!$G$11 -> 0.025 | O53: =Assumptions!$G$11 -> 0.025 | P53: =Assumptions!$G$11 -> 0.025 | Q53: =Assumptions!$G$11 -> 0.025
...

Sheet DCF
E2: =Assumptions!G4 -> 2026 | F2: =E2+1 -> 2027 | G2: =F2+1 -> 2028 | H2: =G2+1 -> 2029 | I2: =H2+1 -> 2030 | K2: Assumptions
B3: Time Periods | E3: 1 | F3: =E3+1 -> 2 | G3: =F3+1 -> 3 | H3: =G3+1 -> 4 | I3: =H3+1 -> 5
B4: EBIT | E4: =Model!M84 -> 9076.0828 | F4: =Model!N84 -> 10037.57 | G4: =Model!O84 -> 11047.168 | H4: =Model!P84 -> 12061.886 | I4: =Model!Q84 -> 13162.802 | K4: Discount Rate(WACC) | N4: 0.09
B5: Add: D&A | E5: =Model!M164 -> 802.83933 | F5: =Model!N164 -> 750.69493 | G5: =Model!O164 -> 684.97482 | H5: =Model!P164 -> 671.62722 | I5: =Model!Q164 -> 648.6067 | K5: Terminal Multiple | N5: 10
B6: EBITDA | E6: =E4+E5 -> 9878.9221 | F6: =F4+F5 -> 10788.265 | G6: =G4+G5 -> 11732.142 | H6: =H4+H5 -> 12733.513 | I6: =I4+I5 -> 13811.409 | K6: Date of modeling | N6: 46311
B7: Less: Cash Taxes | E7: =E4*Assumptions!$G$5 -> 1815.2166 | F7: =F4*Assumptions!$G$5 -> 2007.514 | G7: =G4*Assumptions!$G$5 -> 2209.4335 | H7: =H4*Assumptions!$G$5 -> 2412.3772 | I7: =I4*Assumptions!$G$5 -> 2632.5604 | K7: Current Price | N7: 214.13
B8: Less: CapEx | E8: =-Model!M174+Model!M175+Model!M176+Model!M177 -> 120 | F8: =-Model!N174+Model!N175+Model!N176+Model!N177 -> 120 | G8: =-Model!O174+Model!O175+Model!O176+Model!O177 -> 120 | H8: =-Model!P174+Model!P175+Model!P176+Model!P177 -> 120 | I8: =-Model!Q174+Model!Q175+Model!Q176+Model!Q177 -> 120 | K8: Estimated Shares Outstanding, in Millions | N8: 403
B9: Less: Changes in NWC | E9: =Model!M236 -> 97.805277 | F9: =Model!N236 -> 663.51949 | G9: =Model!O236 -> 703.21993 | H9: =Model!P236 -> 723.82713 | I9: =Model!Q236 -> 793.9839 | K9: Cash | N9: =Model!M111 -> 5176.7472
B10: Unlevered FCF | E10: =E6-E7-E8-E9 -> 7845.9003 | F10: =F6-F7-F8-F9 -> 7997.2316 | G10: =G6-G7-G8-G9 -> 8699.489 | H10: =H6-H7-H8-H9 -> 9477.3087 | I10: =I6-I7-I8-I9 -> 10264.865 | K10: Debt | N10: =Model!M126+Model!M132 -> 4860
B11: Discounted Unlevered FCF | E11: =E10/(1+$N$4)^E3 -> 7198.0736 | F11: =F10/(1+$N$4)^F3 -> 6731.1098 | G11: =G10/(1+$N$4)^G3 -> 6717.6017 | H11: =H10/(1+$N$4)^H3 -> 6713.9644 | I11: =I10/(1+$N$4)^I3 -> 6671.4577
B12: PV of Unlevered FCF | I12: =SUM(E11:I11) -> 34032.207
B14: Intrinsic Value | G14: Market Value
E15: ($ MM) | I15: ($ MM)
B16: Terminal Value | E16: =E6*N5 -> 98789.221 | G16: Market Cap | I16: =N8*N7 -> 86294.39
B17: Present Value of Terminal Value | E17: =E16/(1+$N$4)^I3 -> 64206.215 | G17: Plus: Debt | I17: =N10 -> 4860
B18: Implied TEV / Present Value | E18: =E17+I12 -> 98238.423 | G18: Less: Cash | I18: =N9 -> 5176.7472
B19: Plus: Cash | E19: =N9 -> 5176.7472 | G19: Enterprise Value | I19: =I16+I17-I18 -> 85977.643
B20: Less:Debt | E20: =N10 -> 4860
B21: Implied Equity Value | E21: =E18+E19-E20 -> 98555.17 | G21: Market Value vs Intrinsic Value
B22: SharesOutstanding | E22: =N8 -> 403 | G22: Market Value | I22: =N7 -> 214.13
B23: Implied Share Price | E23: =E21/E22 -> 244.55377 | G23: Change | I23: =I24-I22 -> 30.423771
B24: Implied Upside / Downside | E24: =(E23-N7)/N7 -> 0.14208084 | G24: Intrinsic Value | I24: =E23 -> 244.55377
D27: Enterprise Value
E28: Terminal Value | K28: Step-ups
C29: EV | D29: =E18 -> 98238.423 | E29: =F29-$L$29 -> 8 | F29: =G29-$L$29 -> 9 | G29: 10 | H29: =G29+$L$29 -> 11 | I29: =H29+$L$29 -> 12 | K29: Row | L29: 1
D30: =D31-$L$30 -> 0.08 | E30: 88766.621 | F30: 95490.049 | G30: 102213.48 | H30: 108936.91 | I30: 115660.33 | K30: Column | L30: 0.005
D31: =D32-$L$30 -> 0.085 | E31: 87060.074 | F31: 93630.006 | G31: 100199.94 | H31: 106769.87 | I31: 113339.8
C32: WACC | D32: 0.09 | E32: 85397.18 | F32: 91817.801 | G32: 98238.423 | H32: 104659.04 | I32: 111079.67
D33: =D32+$L$30 -> 0.095 | E33: 83776.599 | F33: 90051.964 | G33: 96327.328 | H33: 102602.69 | I33: 108878.06
D34: =D33+$L$30 -> 0.1 | E34: 82197.043 | F34: 88331.077 | G34: 94465.11 | H34: 100599.14 | I34: 106733.18
D36: Implied Share Price
E37: Terminal Value
C38: Price | D38: =E23 -> 244.55377 | E38: =F38-$L$29 -> 8 | F38: =G38-$L$29 -> 9 | G38: 10 | H38: =G38+$L$29 -> 11 | I38: =H38+$L$29 -> 12
D39: =D40-$L$30 -> 0.08 | E39: 221.05054 | F39: 237.73399 | G39: 254.41743 | H39: 271.10088 | I39: 287.78432
D40: =D41-$L$30 -> 0.085 | E40: 216.81593 | F40: 233.1185 | G40: 249.42106 | H40: 265.72362 | I40: 282.02618
C41: WACC | D41: 0.09 | E41: 212.68964 | F41: 228.62171 | G41: 244.55377 | H41: 260.48583 | I41: 276.4179
D42: =D41+$L$30 -> 0.095 | E42: 208.66835 | F42: 224.23998 | G42: 239.8116 | H42: 255.38323 | I42: 270.95485
D43: =D42+$L$30 -> 0.1 | E43: 204.74886 | F43: 219.96979 | G43: 235.19071 | H43: 250.41164 | I43: 265.63257

Sheet Scenarios
B1: =COVER!B8 -> Adobe Inc.
B2: Scenarios
B5: Scenario Switch: | E5: 1 | I5: =Assumptions!$G$4 -> 2026 | J5: =I5+1 -> 2027 | K5: =J5+1 -> 2028 | L5: =K5+1 -> 2029 | M5: =L5+1 -> 2030
B8: YoY Growth, by Customer Group
C9: Creative & Marketing Professionals, DM & DX | I9: =CHOOSE($E$5,I11,I12,I13) -> 0.1 | J9: =CHOOSE($E$5,J11,J12,J13) -> 0.098 | K9: =CHOOSE($E$5,K11,K12,K13) -> 0.095 | L9: =CHOOSE($E$5,L11,L12,L13) -> 0.093 | M9: =CHOOSE($E$5,M11,M12,M13) -> 0.092
D11: Base Case | I11: 0.1 | J11: 0.098 | K11: 0.095 | L11: 0.093 | M11: 0.092
D12: Best Case | I12: 0.105 | J12: 0.1 | K12: 0.098 | L12: 0.098 | M12: 0.098
D13: Worst Case | I13: 0.09 | J13: 0.08 | K13: 0.08 | L13: 0.075 | M13: 0.07
C15: Business Professionals & Consumers, DM&DX | I15: =CHOOSE($E$5,I17,I18,I19) -> 0.11 | J15: =CHOOSE($E$5,J17,J18,J19) -> 0.11 | K15: =CHOOSE($E$5,K17,K18,K19) -> 0.1 | L15: =CHOOSE($E$5,L17,L18,L19) -> 0.09 | M15: =CHOOSE($E$5,M17,M18,M19) -> 0.09
D17: Base Case | I17: 0.11 | J17: 0.11 | K17: 0.1 | L17: 0.09 | M17: 0.09
D18: Best Case | I18: 0.12 | J18: 0.11 | K18: 0.11 | L18: 0.1 | M18: 0.1
D19: Worst Case | I19: 0.1 | J19: 0.1 | K19: 0.08 | L19: 0.08 | M19: 0.07
