Workbook
Name E：GM: Returns!$K$1

Sheet COVER
B8: Portfolio Risk & Return Analysis
B10: September 2026
B25: Name
B26: Note: This model is created strictly for educational and portfolio demonstration purposes. It does not constitute investment advice or an offer to buy/sell any financial instruments.
B27: *The data on this page, as well as the "Prices" and "Returns" sheets, is derived from historical backtesting as the portfolio has less than one year live porformance history. Past performance, whether actual or backtested, is no guarantee of future results.

Sheet Dashboard
C2: Overview | O2: Industry Breakdown
C4: Total Active Amount | F4: =SUM(Holdings[Approx. Total Amount Held]) -> 128487.07 | H4: Annualized Return | K4: =AVERAGE(_xlfn.ANCHORARRAY(Returns!B2)) * 252 -> 0.20808476 | O4: {=_xlfn.UNIQUE(Holdings[Industry])} -> Software & IT Services | R4: {=SUMIF(Holdings[Industry],_xlfn.ANCHORARRAY( O4), Holdings[Weight])} -> 0.21689575
C5: Number of Positions | F5: =COUNTA(Holdings[Ticker]) -> 17 | H5: Annualized Volatility | K5: =_xlfn.STDEV.S(_xlfn.ANCHORARRAY(Returns!B2))*SQRT(252) -> 0.14446556 | O5: Machinery, Equipment & Components | R5: 0.054924204
C6: Beta | F6: =SUMPRODUCT(Holdings[Weight],Holdings[Beta]) -> 1.1345338 | H6: Alpha | K6: {=_xlfn.LET(_xlpm.rp,_xlfn.ANCHORARRAY(Returns!B2),_xlpm.rm,_xlfn.ANCHORARRAY(Returns!F2),_xlpm.rf_daily, F16/ 252,_xlpm.y, _xlpm.rp - _xlpm.rf_daily,_xlpm.x, _xlpm.rm - _xlpm.rf_daily,_xlpm.alpha_daily, INTERCEPT(_xlpm.y, _xlpm.x),_xlpm.alpha_daily * 252)} -> 0.088441314 | O6: Banking Services | R6: 0.10034084
O7: Beverages | R7: 0.050189875
O8: Semiconductors & Semiconductor Equipment | R8: 0.12152974
C9: Risk Analysis | O9: Food & Drug Retailing | R9: 0.036928229
O10: Computers, Phones & Household Electronics | R10: 0.13424308
C11: Risk Adjusted Return | H11: Tail Risk Analysis | O11: Investment Banking & Investment Services | R11: 0.032127746
C12: Sharpe Ratio | F12: =(K4-F16)/K5 -> 1.1538027 | H12: Maximum Drawdown | K12: =MIN(Returns!E:E) -> -0.086860578 | O12: Diversified Retail | R12: 0.10479669
C13: Sortino Ratio | F13: {=(AVERAGE(Returns!B2:B250)*252 - F16) /(SQRT(SUMSQ(IF(Returns!B2:B250 < F16/252, Returns!B2:B250-F16/252, 0)) / (COUNT(Returns!B2:B250) - 1)) * SQRT(249))} -> 1.7515907 | H13: Recovery Time | K13: {=IFERROR(INDEX(Returns!A:A,_xlfn.XMATCH(MIN(Returns!E:E),Returns!E:E)+_xlfn.XMATCH(0,INDEX(Returns!E:E,_xlfn.XMATCH(MIN(Returns!E:E),Returns!E:E)):INDEX(Returns!E:E,300),1)-1)-INDEX(Returns!A:A,_xlfn.XMATCH(MIN(Returns!E:E),Returns!E:E)),"Recovering")} -> 39 | O13: Oil & Gas | R13: 0.1254815
O14: Telecommunications Services | R14: 0.022542346
B16: Risk-free Return* | F16: 0.0414 | O16: Top 1 Industry Concentration | R16: =MAX(_xlfn.ANCHORARRAY(R4)) -> 0.21689575
O17: Top 3 Industry Concentration | R17: =SUM(_xlfn.CHOOSEROWS(_xlfn._xlws.SORT(_xlfn.ANCHORARRAY(R4), 1, -1), 1, 2, 3)) -> 0.47662033
B18: *The risk-free rate is benchmarked against the 3-Month U.S. Treasury Bill rate. | O18: HHI Index | R18: =SUMSQ(Holdings[Weight]) -> 0.076433375
B19: *Simulated performance has inherent limitations, as it is prepared with the benefit of hindsight.

Sheet Holdings
A1: Company Name | B1: Ticker | C1: Industry | D1: Current Price | E1: Position Size | F1: Approx. Total Amount Held | G1: Weight | H1: Beta | I1: Size
A2: #VALUE! | B2: {=_FV(A2,"Ticker symbol",TRUE)} -> GOOG | C2: {=_FV(A2,"Industry")} -> Software & IT Services | D2: {=_FV(A2,"price")} -> 320.59 | E2: 30 | F2: =E2*D2 -> 9617.7 | G2: =F2/SUM(F:F) -> 0.074853446 | H2: {=_FV(A2,"Beta")} -> 1.203 | I2: {=LN(_FV(Holdings[[#This Row],[Company Name]],"Market cap",TRUE))} -> 28.997321
A3: #VALUE! | B3: {=_FV(A3,"Ticker symbol",TRUE)} -> CRWV | C3: {=_FV(A3,"Industry")} -> Software & IT Services | D3: {=_FV(A3,"price")} -> 60.595 | E3: 40 | F3: =E3*D3 -> 2423.8 | G3: =F3/SUM(F:F) -> 0.018864155 | H3: {=_FV(A3,"Beta")} -> 2.989 | I3: {=LN(_FV(Holdings[[#This Row],[Company Name]],"Market cap",TRUE))} -> 24.232431
A4: #VALUE! | B4: {=_FV(A4,"Ticker symbol",TRUE)} -> VRT | C4: {=_FV(A4,"Industry")} -> Machinery, Equipment & Components | D4: {=_FV(A4,"price")} -> 235.235 | E4: 30 | F4: =E4*D4 -> 7057.05 | G4: =F4/SUM(F:F) -> 0.054924204 | H4: {=_FV(A4,"Beta")} -> 2.1039 | I4: {=LN(_FV(Holdings[[#This Row],[Company Name]],"Market cap",TRUE))} -> 25.229308
A5: #VALUE! | B5: {=_FV(A5,"Ticker symbol",TRUE)} -> HSBC | C5: {=_FV(A5,"Industry")} -> Banking Services | D5: {=_FV(A5,"price")} -> 85.95 | E5: 150 | F5: =E5*D5 -> 12892.5 | G5: =F5/SUM(F:F) -> 0.10034084 | H5: {=_FV(A5,"Beta")} -> 0.5363 | I5: {=LN(_FV(Holdings[[#This Row],[Company Name]],"Market cap",TRUE))} -> 26.408718
A6: #VALUE! | B6: {=_FV(A6,"Ticker symbol",TRUE)} -> KO | C6: {=_FV(A6,"Industry")} -> Beverages | D6: {=_FV(A6,"price")} -> 92.125 | E6: 70 | F6: =E6*D6 -> 6448.75 | G6: =F6/SUM(F:F) -> 0.050189875 | H6: {=_FV(A6,"Beta")} -> 0.2949 | I6: {=LN(_FV(Holdings[[#This Row],[Company Name]],"Market cap",TRUE))} -> 26.70562
A7: #VALUE! | B7: {=_FV(A7,"Ticker symbol",TRUE)} -> NVDA | C7: {=_FV(A7,"Industry")} -> Semiconductors & Semiconductor Equipment | D7: {=_FV(A7,"price")} -> 217.3 | E7: 40 | F7: =E7*D7 -> 8692 | G7: =F7/SUM(F:F) -> 0.06764883 | H7: {=_FV(A7,"Beta")} -> 2.1891 | I7: {=LN(_FV(Holdings[[#This Row],[Company Name]],"Market cap",TRUE))} -> 29.286757
A8: #VALUE! | B8: {=_FV(A8,"Ticker symbol",TRUE)} -> WMT | C8: {=_FV(A8,"Industry")} -> Food & Drug Retailing | D8: {=_FV(A8,"price")} -> 118.62 | E8: 40 | F8: =E8*D8 -> 4744.8 | G8: =F8/SUM(F:F) -> 0.036928229 | H8: {=_FV(A8,"Beta")} -> 0.5657 | I8: {=LN(_FV(Holdings[[#This Row],[Company Name]],"Market cap",TRUE))} -> 27.570316
A9: #VALUE! | B9: {=_FV(A9,"Ticker symbol",TRUE)} -> MSFT | C9: {=_FV(A9,"Industry")} -> Software & IT Services | D9: {=_FV(A9,"price")} -> 527.56 | E9: 30 | F9: =E9*D9 -> 15826.8 | G9: =F9/SUM(F:F) -> 0.12317815 | H9: {=_FV(A9,"Beta")} -> 1.0486 | I9: {=LN(_FV(Holdings[[#This Row],[Company Name]],"Market cap",TRUE))} -> 28.996573
A10: #VALUE! | B10: {=_FV(A10,"Ticker symbol",TRUE)} -> AAPL | C10: {=_FV(A10,"Industry")} -> Computers, Phones & Household Electronics | D10: {=_FV(A10,"price")} -> 344.97 | E10: 50 | F10: =E10*D10 -> 17248.5 | G10: =F10/SUM(F:F) -> 0.13424308 | H10: {=_FV(A10,"Beta")} -> 1.0795 | I10: {=LN(_FV(Holdings[[#This Row],[Company Name]],"Market cap",TRUE))} -> 29.247346
A11: #VALUE! | B11: {=_FV(A11,"Ticker symbol",TRUE)} -> AVGO | C11: {=_FV(A11,"Industry")} -> Semiconductors & Semiconductor Equipment | D11: {=_FV(A11,"price")} -> 346.15 | E11: 20 | F11: =E11*D11 -> 6923 | G11: =F11/SUM(F:F) -> 0.053880908 | H11: {=_FV(A11,"Beta")} -> 1.4911 | I11: {=LN(_FV(Holdings[[#This Row],[Company Name]],"Market cap",TRUE))} -> 28.133245
A12: #VALUE! | B12: {=_FV(A12,"Ticker symbol",TRUE)} -> IBKR | C12: {=_FV(A12,"Industry")} -> Investment Banking & Investment Services | D12: {=_FV(A12,"price")} -> 82.56 | E12: 50 | F12: =E12*D12 -> 4128 | G12: =F12/SUM(F:F) -> 0.032127746 | H12: {=_FV(A12,"Beta")} -> 1.3588 | I12: {=LN(_FV(Holdings[[#This Row],[Company Name]],"Market cap",TRUE))} -> 25.669661
A13: #VALUE! | B13: {=_FV(A13,"Ticker symbol",TRUE)} -> COST | C13: {=_FV(A13,"Industry")} -> Diversified Retail | D13: {=_FV(A13,"price")} -> 982.52 | E13: 6 | F13: =E13*D13 -> 5895.12 | G13: =F13/SUM(F:F) -> 0.045881037 | H13: {=_FV(A13,"Beta")} -> 0.8629 | I13: {=LN(_FV(Holdings[[#This Row],[Company Name]],"Market cap",TRUE))} -> 26.799493
... A18: #VALUE! | B18: {=_FV(A18,"Ticker symbol",TRUE)} -> SPCX | C18: {=_FV(A18,"Industry")} -> Telecommunications Services | D18: {=_FV(A18,"price")} -> 144.82 | E18: 20 | F18: =E18*D18 -> 2896.4 | G18: =F18/SUM(F:F) -> 0.022542346 | H18: {=_FV(A18,"Beta")} -> 3.179 | I18: {=LN(_FV(Holdings[[#This Row],[Company Name]],"Market cap",TRUE))} -> 28.307434

Sheet Holdings - ordered by weight
A1: Company Name | B1: Ticker | C1: Industry | D1: Current Price | E1: Position Size | F1: Approx. Total Amount Held | G1: Weight | H1: Beta | I1: Size
A2: {=_xlfn.SORTBY(Holdings[], Holdings[Weight], -1)} -> #VALUE! | B2: AAPL | C2: Computers, Phones & Household Electronics | D2: 344.97 | E2: 50 | F2: 17248.5 | G2: 0.13424308 | H2: 1.0795 | I2: 29.247346
A3: #VALUE! | B3: MSFT | C3: Software & IT Services | D3: 527.56 | E3: 30 | F3: 15826.8 | G3: 0.12317815 | H3: 1.0486 | I3: 28.996573
A4: #VALUE! | B4: HSBC | C4: Banking Services | D4: 85.95 | E4: 150 | F4: 12892.5 | G4: 0.10034084 | H4: 0.5363 | I4: 26.408718
A5: #VALUE! | B5: GOOG | C5: Software & IT Services | D5: 320.59 | E5: 30 | F5: 9617.7 | G5: 0.074853446 | H5: 1.203 | I5: 28.997321
A6: #VALUE! | B6: NVDA | C6: Semiconductors & Semiconductor Equipment | D6: 217.3 | E6: 40 | F6: 8692 | G6: 0.06764883 | H6: 2.1891 | I6: 29.286757
A7: #VALUE! | B7: AMZN | C7: Diversified Retail | D7: 252.33 | E7: 30 | F7: 7569.9 | G7: 0.058915656 | H7: 1.4918 | I7: 28.632281
A8: #VALUE! | B8: VRT | C8: Machinery, Equipment & Components | D8: 235.235 | E8: 30 | F8: 7057.05 | G8: 0.054924204 | H8: 2.1039 | I8: 25.229308
A9: #VALUE! | B9: CVX | C9: Oil & Gas | D9: 231.465 | E9: 30 | F9: 6943.95 | G9: 0.054043959 | H9: 0.4799 | I9: 26.848653
A10: #VALUE! | B10: AVGO | C10: Semiconductors & Semiconductor Equipment | D10: 346.15 | E10: 20 | F10: 6923 | G10: 0.053880908 | H10: 1.4911 | I10: 28.133245
A11: #VALUE! | B11: KO | C11: Beverages | D11: 92.125 | E11: 70 | F11: 6448.75 | G11: 0.050189875 | H11: 0.2949 | I11: 26.70562
A12: #VALUE! | B12: COP | C12: Oil & Gas | D12: 150.24 | E12: 40 | F12: 6009.6 | G12: 0.046772021 | H12: 0.2082 | I12: 25.918936
A13: #VALUE! | B13: COST | C13: Diversified Retail | D13: 982.52 | E13: 6 | F13: 5895.12 | G13: 0.045881037 | H13: 0.8629 | I13: 26.799493
A14: #VALUE! | B14: WMT | C14: Food & Drug Retailing | D14: 118.62 | E14: 40 | F14: 4744.8 | G14: 0.036928229 | H14: 0.5657 | I14: 27.570316
... A18: #VALUE! | B18: CRWV | C18: Software & IT Services | D18: 60.595 | E18: 40 | F18: 2423.8 | G18: 0.018864155 | H18: 2.989 | I18: 24.232431

Sheet Prices
A1: DATE | B1: {=_xlfn.TOROW(_xlfn.DROP(Holdings!B:B,1),1)} -> GOOG | C1: CRWV | D1: VRT | E1: HSBC | F1: KO | G1: NVDA | H1: WMT | I1: MSFT | J1: AAPL | K1: AVGO | L1: IBKR | M1: COST | N1: AMZN | O1: COP | P1: CVX | Q1: SHEL | R1: SPCX
A2: {=_xlfn.CHOOSECOLS(_xlfn.STOCKHISTORY("SPY", TODAY()-365, TODAY(), 0, 0, 0, 1), 1)} -> 45958 | B2: {=IF(B$1="", "", _xlfn.LET(_xlpm.history, _xlfn.STOCKHISTORY(B$1, TODAY()-365, TODAY(), 0, 0, 0, 1),_xlfn.IFNA(_xlfn.XLOOKUP(_xlfn.ANCHORARRAY($A2), _xlfn.CHOOSECOLS(_xlpm.history, 1), _xlfn.CHOOSECOLS(_xlpm.history, 2), NA()), NA())))} -> 268.43 | C2: {=IF(C$1="", "", _xlfn.LET(_xlpm.history, _xlfn.STOCKHISTORY(C$1, TODAY()-365, TODAY(), 0, 0, 0, 1),_xlfn.IFNA(_xlfn.XLOOKUP(_xlfn.ANCHORARRAY($A2), _xlfn.CHOOSECOLS(_xlpm.history, 1), _xlfn.CHOOSECOLS(_xlpm.history, 2), NA()), NA())))} -> 134.8 | D2: {=IF(D$1="", "", _xlfn.LET(_xlpm.history, _xlfn.STOCKHISTORY(D$1, TODAY()-365, TODAY(), 0, 0, 0, 1),_xlfn.IFNA(_xlfn.XLOOKUP(_xlfn.ANCHORARRAY($A2), _xlfn.CHOOSECOLS(_xlpm.history, 1), _xlfn.CHOOSECOLS(_xlpm.history, 2), NA()), NA())))} -> 190.57 | E2: {=IF(E$1="", "", _xlfn.LET(_xlpm.history, _xlfn.STOCKHISTORY(E$1, TODAY()-365, TODAY(), 0, 0, 0, 1),_xlfn.IFNA(_xlfn.XLOOKUP(_xlfn.ANCHORARRAY($A2), _xlfn.CHOOSECOLS(_xlpm.history, 1), _xlfn.CHOOSECOLS(_xlpm.history, 2), NA()), NA())))} -> 70.04 | F2: {=IF(F$1="", "", _xlfn.LET(_xlpm.history, _xlfn.STOCKHISTORY(F$1, TODAY()-365, TODAY(), 0, 0, 0, 1),_xlfn.IFNA(_xlfn.XLOOKUP(_xlfn.ANCHORARRAY($A2), _xlfn.CHOOSECOLS(_xlpm.history, 1), _xlfn.CHOOSECOLS(_xlpm.history, 2), NA()), NA())))} -> 70.16 | G2: {=IF(G$1="", "", _xlfn.LET(_xlpm.history, _xlfn.STOCKHISTORY(G$1, TODAY()-365, TODAY(), 0, 0, 0, 1),_xlfn.IFNA(_xlfn.XLOOKUP(_xlfn.ANCHORARRAY($A2), _xlfn.CHOOSECOLS(_xlpm.history, 1), _xlfn.CHOOSECOLS(_xlpm.history, 2), NA()), NA())))} -> 8.24 | H2: {=IF(H$1="", "", _xlfn.LET(_xlpm.history, _xlfn.STOCKHISTORY(H$1, TODAY()-365, TODAY(), 0, 0, 0, 1),_xlfn.IFNA(_xlfn.XLOOKUP(_xlfn.ANCHORARRAY($A2), _xlfn.CHOOSECOLS(_xlpm.history, 1), _xlfn.CHOOSECOLS(_xlpm.history, 2), NA()), NA())))} -> 103.17 | I2: {=IF(I$1="", "", _xlfn.LET(_xlpm.history, _xlfn.STOCKHISTORY(I$1, TODAY()-365, TODAY(), 0, 0, 0, 1),_xlfn.IFNA(_xlfn.XLOOKUP(_xlfn.ANCHORARRAY($A2), _xlfn.CHOOSECOLS(_xlpm.history, 1), _xlfn.CHOOSECOLS(_xlpm.history, 2), NA()), NA())))} -> 542.07 | ... IP2: {=IF(IP$1="", "", _xlfn.LET(_xlpm.history, _xlfn.STOCKHISTORY(IP$1, TODAY()-365, TODAY(), 0, 0, 0, 1),_xlfn.IFNA(_xlfn.XLOOKUP(_xlfn.ANCHORARRAY($A2), _xlfn.CHOOSECOLS(_xlpm.history, 1), _xlfn.CHOOSECOLS(_xlpm.history, 2), NA()), NA())))}
A3: 45959 | B3: 275.17 | C3: 139.93 | D3: 199.27 | E3: 70.49 | F3: 68.35 | G3: 8.6 | H3: 102.46 | I3: 541.55 | J3: 269.7 | K3: 385.98 | L3: 69.19 | M3: 912.42 | N3: 230.3 | O3: 88.08 | P3: 155.1 | Q3: 75.55 | R3: #N/A
A4: 45960 | B4: 281.9 | C4: 131.06 | D4: 193.76 | E4: 70.37 | F4: 68.98 | G4: 8.21 | H4: 102.23 | I4: 525.76 | J4: 271.4 | K4: 376.47 | L4: 68.51 | M4: 920.18 | N4: 222.86 | O4: 88.14 | P4: 153.52 | Q4: 74.73 | R4: #N/A
A5: 45961 | B5: 281.82 | C5: 133.71 | D5: 192.86 | E5: 70.07 | F5: 68.9 | G5: 8.6 | H5: 101.18 | I5: 517.81 | J5: 270.37 | K5: 369.63 | L5: 70.36 | M5: 911.45 | N5: 244.22 | O5: 88.86 | P5: 157.72 | Q5: 74.92 | R5: #N/A
A6: 45964 | B6: 284.12 | C6: 126.32 | D6: 191.4 | E6: 70.46 | F6: 67.97 | G6: 8.91 | H6: 101.59 | I6: 517.03 | J6: 269.05 | K6: 362.55 | L6: 73.08 | M6: 928.04 | N6: 254 | O6: 88.57 | P6: 154.04 | Q6: 74.39 | R6: #N/A
A7: 45965 | B7: 278.06 | C7: 115.75 | D7: 180.82 | E7: 69.85 | F7: 68.66 | G7: 8.52 | H7: 102.27 | I7: 514.33 | J7: 270.04 | K7: 351.94 | L7: 70.69 | M7: 940.74 | N7: 249.32 | O7: 87.91 | P7: 153.39 | Q7: 73.74 | R7: #N/A
A8: 45966 | B8: 284.75 | C8: 114.42 | D8: 190.71 | E8: 70.92 | F8: 68.51 | G8: 8.53 | H8: 101.47 | I8: 507.16 | J8: 270.14 | K8: 358.98 | L8: 71.62 | M8: 935.03 | N8: 250.2 | O8: 87.7 | P8: 152.66 | Q8: 74.61 | R8: #N/A
A9: 45967 | B9: 285.34 | C9: 106.93 | D9: 183.02 | E9: 72.01 | F9: 69.06 | G9: 8 | H9: 101.68 | I9: 497.1 | J9: 269.77 | K9: 355.59 | L9: 69.86 | M9: 923.58 | N9: 243.04 | O9: 85.66 | P9: 152.94 | Q9: 74.22 | R9: #N/A
A10: 45968 | B10: 279.7 | C10: 104.01 | D10: 179.8 | E10: 71.27 | F10: 70.55 | G10: 7.8 | H10: 102.59 | I10: 496.82 | J10: 268.47 | K10: 349.43 | L10: 70.54 | M10: 922.74 | N10: 244.41 | O10: 86.83 | P10: 155.02 | Q10: 75.59 | R10: #N/A
A11: 45971 | B11: 290.59 | C11: 105.61 | D11: 187.84 | E11: 72.04 | F11: 70.52 | G11: 8.25 | H11: 102.42 | I11: 506 | J11: 269.43 | K11: 358.39 | L11: 71.13 | M11: 915.56 | N11: 248.4 | O11: 88.23 | P11: 155.65 | Q11: 76.56 | R11: #N/A
A12: 45972 | B12: 291.74 | C12: 88.39 | D12: 179.05 | E12: 72.53 | F12: 71.61 | G12: 8.2 | H12: 103.44 | I12: 508.68 | J12: 275.25 | K12: 351.96 | L12: 70.87 | M12: 913.86 | N12: 249.1 | O12: 90.69 | P12: 156.24 | Q12: 77.01 | R12: #N/A
A13: 45973 | B13: 287.43 | C13: 85.43 | D13: 173.37 | E13: 73.49 | F13: 71.51 | G13: 8.24 | H13: 103.44 | I13: 511.14 | J13: 273.47 | K13: 355.22 | L13: 72.7 | M13: 914 | N13: 244.2 | O13: 89.07 | P13: 153.32 | Q13: 76.41 | R13: #N/A
A14: 45974 | B14: 279.12 | C14: 78.34 | D14: 163.64 | E14: 73.16 | F14: 71.07 | G14: 8.17 | H14: 102.54 | I14: 503.29 | J14: 272.95 | K14: 339.98 | L14: 67.04 | M14: 925.08 | N14: 237.58 | O14: 89.42 | P14: 155.58 | Q14: 75.92 | R14: #N/A
... A20: 45982 | B20: 299.65 | C20: 71.65 | D20: 159.83 | E20: 68.96 | F20: 72.95 | G20: 7.58 | H20: 105.32 | I20: 472.12 | J20: 271.49 | K20: 340.2 | L20: 61.05 | M20: 899.01 | N20: 220.69 | O20: 87.37 | P20: 149.98 | Q20: 73.27 | R20: #N/A
A21: 45985 | B21: 318.47 | C21: 73.6 | D21: 168.91 | E21: 68.95 | F21: 72.59 | G21: #N/A | H21: 104.06 | I21: 474 | J21: 275.92 | K21: 377.96 | L21: 62.43 | M21: 886.12 | N21: 226.28 | O21: 87.56 | P21: 149.75 | Q21: 73.23 | R21: #N/A
A22: 45986 | B22: 323.64 | C22: 71.29 | D22: 169.57 | E22: 69.51 | F22: 72.61 | G22: 7.34 | H22: 107 | I22: 476.99 | J22: 276.97 | K22: 385.03 | L22: 63.17 | M22: 894.33 | N22: 229.67 | O22: 86.62 | P22: 148.53 | Q22: 72.8 | R22: #N/A
A23: 45987 | B23: 320.28 | C23: 74.29 | D23: 172.02 | E23: 70.58 | F23: 72.88 | G23: 7.57 | H23: 109.1 | I23: 485.5 | J23: 277.55 | K23: 397.57 | L23: 64.19 | M23: 908.26 | N23: 229.16 | O23: 87.09 | P23: 149.51 | Q23: 73.41 | R23: #N/A
A24: 45989 | B24: 320.12 | C24: 73.12 | D24: 179.73 | E24: 71.16 | F24: 73.12 | G24: 7.5 | H24: 110.51 | I24: 492.01 | J24: 278.85 | K24: 402.96 | L24: 65.02 | M24: 913.59 | N24: 233.22 | O24: 88.69 | P24: 151.13 | Q24: 73.77 | R24: #N/A
A25: 45992 | B25: 315.12 | C25: 77.06 | D25: 179.22 | E25: 71.36 | F25: 71.95 | G25: 7.52 | H25: 111.53 | I25: 486.74 | J25: 283.1 | K25: 386.08 | L25: 63.54 | M25: 911.96 | N25: 233.88 | O25: 90.26 | P25: 152.54 | Q25: 74.31 | R25: #N/A
A26: 45993 | B26: 316.02 | C26: 76.03 | D26: 180.91 | E26: 72 | F26: 70.67 | G26: 7.62 | H26: 112.41 | I26: 490 | J26: 286.19 | K26: 381.57 | L26: 63.59 | M26: 922.03 | N26: 234.42 | O26: 89.29 | P26: 150.25 | Q26: 73.96 | R26: #N/A
A27: 45994 | B27: 320.62 | C27: 79.36 | D27: 178.88 | E27: 72.01 | F27: 70.81 | G27: 7.58 | H27: 114.41 | I27: 477.73 | J27: 284.15 | K27: 380.61 | L27: 64.96 | M27: 922.26 | N27: 232.38 | O27: 91.81 | P27: 151.59 | Q27: 75.12 | R27: #N/A
A28: 45995 | B28: 318.39 | C28: 85.75 | D28: 182.54 | E28: 71.71 | F28: 70.45 | G28: 7.64 | H28: 114.84 | I28: 480.84 | J28: 280.7 | K28: 381.03 | L28: 65.95 | M28: 895.855 | N28: 229.11 | O28: 93.12 | P28: 152.26 | Q28: 74.5 | R28: #N/A
A29: 45996 | B29: 322.09 | C29: 88.3 | D29: 189.02 | E29: 71 | F29: 70 | G29: 7.65 | H29: 115.11 | I29: 483.16 | J29: 278.78 | K29: 390.24 | L29: 64.5 | M29: 894.68 | N29: 229.53 | O29: 93.69 | P29: 150 | Q29: 73.01 | R29: #N/A
A30: 45999 | B30: 314.45 | C30: 86.24 | D30: 185.61 | E30: 71.02 | F30: 70.25 | G30: #N/A | H30: 113.56 | I30: 491.02 | J30: 277.89 | K30: 401.1 | L30: 65.81 | M30: 887.52 | N30: 226.89 | O30: 92.88 | P30: 148.71 | Q30: 72.7 | R30: #N/A
A31: 46000 | B31: 317.75 | C31: 90.66 | D31: 178.38 | E31: 70.79 | F31: 70.09 | G31: 7.75 | H31: 115.06 | I31: 492.02 | J31: 277.18 | K31: 406.29 | L31: 65.56 | M31: 888.44 | N31: 227.92 | O31: 93.43 | P31: 148.49 | Q31: 72.55 | R31: #N/A
A32: 46001 | B32: 321 | C32: 88.16 | D32: 181.82 | E32: 74.08 | F32: 70.21 | G32: 7.7 | H32: 113.18 | I32: 478.56 | J32: 278.78 | K32: 412.97 | L32: 66.67 | M32: 874.41 | N32: 231.78 | O32: 96.8 | P32: 151.41 | Q32: 72.88 | R32: #N/A
A33: 46002 | B33: 313.7 | C33: 87.38 | D33: 178.66 | E33: 75.24 | F33: 69.11 | G33: 7.81 | H33: 115.52 | I33: 483.47 | J33: 278.03 | K33: 406.37 | L33: 66.06 | M33: 884.48 | N33: 230.28 | O33: 96.71 | P33: 150.72 | Q33: 72.86 | R33: #N/A
A34: 46003 | B34: 310.52 | C34: 78.59 | D34: 161.27 | E34: 74.99 | F34: 70.52 | G34: 7.79 | H34: 116.7 | I34: 478.53 | J34: 278.28 | K34: 359.93 | L34: 64.15 | M34: 884.47 | N34: 226.19 | O34: 95.54 | P34: 149.99 | Q34: 72.33 | R34: #N/A
A35: 46006 | B35: 309.32 | C35: 72.35 | D35: 161.74 | E35: 75.28 | F35: 70.97 | G35: 7.31 | H35: 116.79 | I35: 474.82 | J35: 274.11 | K35: 339.81 | L35: 62.87 | M35: 860.56 | N35: 222.54 | O35: 94.36 | P35: 149.8 | Q35: 72.23 | R35: #N/A
A36: 46007 | B36: 307.73 | C36: 69.5 | D36: 160.66 | E36: 74.66 | F36: 70.37 | G36: 7.49 | H36: 115.42 | I36: 476.39 | J36: 274.61 | K36: 341.3 | L36: 63.06 | M36: 860.39 | N36: 222.56 | O36: 90.77 | P36: 146.75 | Q36: 70.46 | R36: #N/A
A37: 46008 | B37: 298.06 | C37: 64.55 | D37: 149.83 | E37: 76.1 | F37: 70.67 | G37: 7.43 | H37: 115.66 | I37: 476.12 | J37: 271.84 | K37: 326.02 | L37: 62.45 | M37: 862.65 | N37: 221.27 | O37: 94.96 | P37: 149.52 | Q37: 71.55 | R37: #N/A
A38: 46009 | B38: 303.75 | C38: 67.68 | D38: 154.39 | E38: 76.76 | F38: 70.36 | G38: 7.24 | H38: 114.83 | I38: 483.98 | J38: 272.19 | K38: 329.88 | L38: 62.94 | M38: 857.59 | N38: 226.76 | O38: 92.23 | P38: 147.69 | Q38: 71.31 | R38: #N/A
A39: 46010 | B39: 308.61 | C39: 83 | D39: 159.82 | E39: 77.92 | F39: 70.06 | G39: 7.56 | H39: 114.36 | I39: 485.92 | J39: 273.67 | K39: 340.36 | L39: 64.26 | M39: 855.62 | N39: 227.35 | O39: 91.94 | P39: 147.75 | Q39: 72.02 | R39: #N/A
A40: 46013 | B40: 311.33 | C40: 84.83 | D40: 166.25 | E40: 78.73 | F40: 70.21 | G40: 7.69 | H40: 112.6 | I40: 484.92 | J40: 270.97 | K40: 341.45 | L40: 65.795 | M40: 850 | N40: 228.43 | O40: 93.31 | P40: 149.8 | Q40: 72.58 | R40: #N/A
A41: 46014 | B41: 315.68 | C41: 80.26 | D41: 166.26 | E41: 79.28 | F41: 69.87 | G41: 7.87 | H41: 110.9 | I41: 486.85 | J41: 272.36 | K41: 349.32 | L41: 65.96 | M41: 854.79 | N41: 232.14 | O41: 92.73 | P41: 150.51 | Q41: 73.07 | R41: #N/A
A42: 46015 | B42: 315.67 | C42: 78.87 | D42: 166.87 | E42: 79.58 | F42: 70.11 | G42: 7.86 | H42: 111.61 | I42: 488.02 | J42: 273.81 | K42: 350.22 | L42: 65.98 | M42: 871.86 | N42: 232.38 | O42: 91.8 | P42: 150.5 | Q42: 72.84 | R42: #N/A
... A45: 46021 | B45: 314.55 | C45: 73.9 | D45: 164.34 | E45: 79.28 | F45: 70.07 | G45: 7.92 | H45: 111.92 | I45: 487.48 | J45: 273.08 | K45: 349.85 | L45: 65 | M45: 865.65 | N45: 232.53 | O45: 94.1 | P45: 152.31 | Q45: 73.83 | R45: #N/A
A46: 46022 | B46: 313.8 | C46: 71.61 | D46: 162.01 | E46: 78.67 | F46: 69.91 | G46: #N/A | H46: 111.41 | I46: 483.62 | J46: 271.86 | K46: 346.1 | L46: 64.31 | M46: 862.34 | N46: 230.82 | O46: 93.61 | P46: 152.41 | Q46: 73.48 | R46: #N/A
A47: 46024 | B47: 315.32 | C47: 79.32 | D47: 175.61 | E47: 80.45 | F47: 69.12 | G47: 8.1 | H47: 112.76 | I47: 472.94 | J47: 271.01 | K47: 347.62 | L47: 67.23 | M47: 854.5 | N47: 226.5 | O47: 96.7 | P47: 155.9 | Q47: 75.44 | R47: #N/A
...

Sheet Returns
A1: DATE | B1: Portfolio Return | C1: Cumulative NAV (Portfolio) | D1: Peak | E1: Drawdown | F1: Benchmark Return (SPY) | G1: Cumulative NAV (SPY) | H1: Benchmark Return (QQQ) | I1: Cumulative NAV (QQQ) | J1: {=_xlfn.ANCHORARRAY(Prices!B1)} -> GOOG | K1: CRWV | L1: VRT | M1: HSBC | N1: KO | O1: NVDA | P1: WMT | Q1: MSFT | R1: AAPL | S1: AVGO | T1: IBKR | U1: COST | V1: AMZN | W1: COP | X1: CVX | Y1: SHEL | Z1: SPCX
A2: {=_xlfn.DROP(_xlfn.ANCHORARRAY(Prices!A2), 1)} -> 45959 | B2: {=MMULT(_xlfn.TAKE(J2:AF499, ROWS(_xlfn.ANCHORARRAY(A2)), COLUMNS(_xlfn.ANCHORARRAY(J1))), Holdings[Weight]) / SUM(Holdings[Weight])} -> 0.010399482 | C2: 1 | D2: =C2 -> 1 | E2: =(C2-D2)/D2 -> 0 | F2: {=_xlfn.LET( _xlpm.bench_code, "SPY", _xlpm.master_dates,_xlfn.ANCHORARRAY( Prices!A2), _xlpm.bench_hist, _xlfn.STOCKHISTORY(_xlpm.bench_code, TODAY()-365, TODAY(), 0, 0, 0, 1), _xlpm.bench_dates, INDEX(_xlpm.bench_hist, , 1), _xlpm.bench_prices, INDEX(_xlpm.bench_hist, , 2), _xlpm.aligned_prices, _xlfn.IFNA(_xlfn.XLOOKUP(_xlpm.master_dates, _xlpm.bench_dates, _xlpm.bench_prices), NA()), _xlpm.p_curr, _xlfn.DROP(_xlpm.aligned_prices, 1), _xlpm.p_prev, _xlfn.DROP(_xlpm.aligned_prices, -1), _xlpm.returns, (_xlpm.p_curr / _xlpm.p_prev) - 1, IFERROR(_xlpm.returns, NA()) )} -> 0.0004803074 | G2: =1 -> 1 | H2: {=_xlfn.LET( _xlpm.bench_code, "QQQ", _xlpm.master_dates,_xlfn.ANCHORARRAY( Prices!A2), _xlpm.bench_hist, _xlfn.STOCKHISTORY(_xlpm.bench_code, TODAY()-365, TODAY(), 0, 0, 0, 1), _xlpm.bench_dates, INDEX(_xlpm.bench_hist, , 1), _xlpm.bench_prices, INDEX(_xlpm.bench_hist, , 2), _xlpm.aligned_prices, _xlfn.IFNA(_xlfn.XLOOKUP(_xlpm.master_dates, _xlpm.bench_dates, _xlpm.bench_prices), NA()), _xlpm.p_curr, _xlfn.DROP(_xlpm.aligned_prices, 1), _xlpm.p_prev, _xlfn.DROP(_xlpm.aligned_prices, -1), _xlpm.returns, (_xlpm.p_curr / _xlpm.p_prev) - 1, IFERROR(_xlpm.returns, NA()) )} -> 0.0045029388 | I2: 1 | J2: {=IF(J$1="", "", _xlfn.LET(_xlpm.prices,_xlfn.ANCHORARRAY( Prices!B2),_xlpm.p_curr, _xlfn.DROP(_xlpm.prices, 1),_xlpm.p_prev, _xlfn.DROP(_xlpm.prices, -1),_xlpm.ret, (_xlpm.p_curr / _xlpm.p_prev) - 1,IFERROR(_xlpm.ret, 0)))} -> 0.025108967 | K2: {=IF(K$1="", "", _xlfn.LET(_xlpm.prices,_xlfn.ANCHORARRAY( Prices!C2),_xlpm.p_curr, _xlfn.DROP(_xlpm.prices, 1),_xlpm.p_prev, _xlfn.DROP(_xlpm.prices, -1),_xlpm.ret, (_xlpm.p_curr / _xlpm.p_prev) - 1,IFERROR(_xlpm.ret, 0)))} -> 0.03805638 | L2: {=IF(L$1="", "", _xlfn.LET(_xlpm.prices,_xlfn.ANCHORARRAY( Prices!D2),_xlpm.p_curr, _xlfn.DROP(_xlpm.prices, 1),_xlpm.p_prev, _xlfn.DROP(_xlpm.prices, -1),_xlpm.ret, (_xlpm.p_curr / _xlpm.p_prev) - 1,IFERROR(_xlpm.ret, 0)))} -> 0.045652516 | M2: {=IF(M$1="", "", _xlfn.LET(_xlpm.prices,_xlfn.ANCHORARRAY( Prices!E2),_xlpm.p_curr, _xlfn.DROP(_xlpm.prices, 1),_xlpm.p_prev, _xlfn.DROP(_xlpm.prices, -1),_xlpm.ret, (_xlpm.p_curr / _xlpm.p_prev) - 1,IFERROR(_xlpm.ret, 0)))} -> 0.0064249001 | N2: {=IF(N$1="", "", _xlfn.LET(_xlpm.prices,_xlfn.ANCHORARRAY( Prices!F2),_xlpm.p_curr, _xlfn.DROP(_xlpm.prices, 1),_xlpm.p_prev, _xlfn.DROP(_xlpm.prices, -1),_xlpm.ret, (_xlpm.p_curr / _xlpm.p_prev) - 1,IFERROR(_xlpm.ret, 0)))} -> -0.025798176 | O2: {=IF(O$1="", "", _xlfn.LET(_xlpm.prices,_xlfn.ANCHORARRAY( Prices!G2),_xlpm.p_curr, _xlfn.DROP(_xlpm.prices, 1),_xlpm.p_prev, _xlfn.DROP(_xlpm.prices, -1),_xlpm.ret, (_xlpm.p_curr / _xlpm.p_prev) - 1,IFERROR(_xlpm.ret, 0)))} -> 0.04368932 | P2: {=IF(P$1="", "", _xlfn.LET(_xlpm.prices,_xlfn.ANCHORARRAY( Prices!H2),_xlpm.p_curr, _xlfn.DROP(_xlpm.prices, 1),_xlpm.p_prev, _xlfn.DROP(_xlpm.prices, -1),_xlpm.ret, (_xlpm.p_curr / _xlpm.p_prev) - 1,IFERROR(_xlpm.ret, 0)))} -> -0.0068818455 | Q2: {=IF(Q$1="", "", _xlfn.LET(_xlpm.prices,_xlfn.ANCHORARRAY( Prices!I2),_xlpm.p_curr, _xlfn.DROP(_xlpm.prices, 1),_xlpm.p_prev, _xlfn.DROP(_xlpm.prices, -1),_xlpm.ret, (_xlpm.p_curr / _xlpm.p_prev) - 1,IFERROR(_xlpm.ret, 0)))} -> -0.0009592857 | ... GT2: {=IF(GT$1="", "", _xlfn.LET(_xlpm.prices,_xlfn.ANCHORARRAY( Prices!GL2),_xlpm.p_curr, _xlfn.DROP(_xlpm.prices, 1),_xlpm.p_prev, _xlfn.DROP(_xlpm.prices, -1),_xlpm.ret, (_xlpm.p_curr / _xlpm.p_prev) - 1,IFERROR(_xlpm.ret, 0)))}
A3: 45960 | B3: -0.010430775 | C3: =C2 * (1 + B3) -> 0.98956923 | D3: =MAX(D2,C3) -> 1 | E3: =(C3-D3)/D3 -> -0.010430775 | F3: -0.010998123 | G3: =G2*(1+F3) -> 0.98900188 | H3: -0.015288548 | I3: =I2*(1+H3) -> 0.98471145 | J3: 0.024457608 | K3: -0.063388837 | L3: -0.027650926 | M3: -0.0017023691 | N3: 0.0092172641 | O3: -0.045348837 | P3: -0.0022447785 | Q3: -0.029157049 | R3: 0.0063033 | S3: -0.024638582 | T3: -0.0098280098 | U3: 0.0085048552 | V3: -0.032305688 | W3: 0.00068119891 | X3: -0.010186976 | Y3: -0.010853739 | Z3: 0
A4: 45961 | B4: 0.0071046877 | C4: =C3 * (1 + B4) -> 0.99659981 | D4: =MAX(D3,C4) -> 1 | E4: =(C4-D4)/D4 -> -0.0034001946 | F4: 0.0032802318 | G4: =G3*(1+F4) -> 0.99224603 | H4: 0.0048238959 | I4: =I3*(1+H4) -> 0.9894616 | J4: -0.00028378858 | K4: 0.020219747 | L4: -0.0046449216 | M4: -0.0042631803 | N4: -0.0011597565 | O4: 0.047503045 | P4: -0.010270958 | Q4: -0.015120968 | R4: -0.0037951363 | S4: -0.018168778 | T4: 0.027003357 | U4: -0.0094872742 | V4: 0.095844925 | W4: 0.0081688223 | X4: 0.027357999 | Y4: 0.0025424863 | Z4: 0
A5: 45964 | B5: 0.0025970155 | C5: =C4 * (1 + B5) -> 0.99918799 | D5: =MAX(D4,C5) -> 1 | E5: =(C5-D5)/D5 -> -0.0008120094 | F5: 0.0018766677 | G5: =G4*(1+F5) -> 0.99410815 | H5: 0.0047848411 | I5: =I4*(1+H5) -> 0.99419601 | J5: 0.0081612377 | K5: -0.055268865 | L5: -0.0075702582 | M5: 0.0055658627 | N5: -0.013497823 | O5: 0.036046512 | P5: 0.0040521842 | Q5: -0.001506344 | R5: -0.0048821985 | S5: -0.019154289 | T5: 0.038658329 | U5: 0.018201766 | V5: 0.04004586 | W5: -0.0032635607 | X5: -0.023332488 | Y5: -0.0070742125 | Z5: 0
A6: 45965 | B6: -0.013310715 | C6: =C5 * (1 + B6) -> 0.98588808 | D6: =MAX(D5,C6) -> 1 | E6: =(C6-D6)/D6 -> -0.014111916 | F6: -0.011853543 | G6: =G5*(1+F6) -> 0.98232444 | H6: -0.020298064 | I6: =I5*(1+H6) -> 0.97401576 | J6: -0.021329016 | K6: -0.083676377 | L6: -0.055276907 | M6: -0.0086573943 | N6: 0.010151537 | O6: -0.043771044 | P6: 0.0066935722 | Q6: -0.0052221341 | R6: 0.0036796135 | S6: -0.029264929 | T6: -0.032703886 | U6: 0.013684755 | V6: -0.018425197 | W6: -0.0074517331 | X6: -0.0042196832 | Y6: -0.0087377336 | Z6: 0
A7: 45966 | B7: 0.0054908091 | C7: =C6 * (1 + B7) -> 0.99130141 | D7: =MAX(D6,C7) -> 1 | E7: =(C7-D7)/D7 -> -0.0086985931 | F7: 0.0034654345 | G7: =G6*(1+F7) -> 0.98572863 | H7: 0.0065078724 | I7: =I6*(1+H7) -> 0.98035453 | J7: 0.024059555 | K7: -0.011490281 | L7: 0.054695277 | M7: 0.01531854 | N7: -0.0021846781 | O7: 0.0011737089 | P7: -0.0078224308 | Q7: -0.013940466 | R7: 0.00037031551 | S7: 0.02000341 | T7: 0.013156033 | U7: -0.0060696898 | V7: 0.0035296005 | W7: -0.0023888067 | X7: -0.0047591108 | Y7: 0.01179821 | Z7: 0
A8: 45967 | B8: -0.012767375 | C8: =C7 * (1 + B8) -> 0.97864509 | D8: =MAX(D7,C8) -> 1 | E8: =(C8-D8)/D8 -> -0.02135491 | F8: -0.01072936 | G8: =G7*(1+F8) -> 0.97515239 | H8: -0.018627262 | I8: =I7*(1+H8) -> 0.96209321 | J8: 0.002071993 | K8: -0.065460584 | L8: -0.040323004 | M8: 0.01536943 | N8: 0.0080280251 | O8: -0.062133646 | P8: 0.0020695772 | Q8: -0.019835949 | R8: -0.0013696602 | S8: -0.009443423 | T8: -0.024574141 | U8: -0.012245596 | V8: -0.028617106 | W8: -0.023261117 | X8: 0.0018341412 | Y8: -0.0052271813 | Z8: 0
A9: 45968 | B9: -0.0034874441 | C9: =C8 * (1 + B9) -> 0.97523212 | D9: =MAX(D8,C9) -> 1 | E9: =(C9-D9)/D9 -> -0.02476788 | F9: 0.00098461906 | G9: =G8*(1+F9) -> 0.97611254 | H9: -0.0031552962 | I9: =I8*(1+H9) -> 0.95905752 | J9: -0.019765893 | K9: -0.027307584 | L9: -0.017593706 | M9: -0.010276351 | N9: 0.021575442 | O9: -0.025 | P9: 0.0089496459 | Q9: -0.00056326695 | R9: -0.0048189198 | S9: -0.017323322 | T9: 0.0097337532 | U9: -0.00090950432 | V9: 0.0056369322 | W9: 0.01365865 | X9: 0.013600105 | Y9: 0.018458636 | Z9: 0
A10: 45971 | B10: 0.016866394 | C10: =C9 * (1 + B10) -> 0.99168077 | D10: =MAX(D9,C10) -> 1 | E10: =(C10-D10)/D10 -> -0.0083192306 | F10: 0.015604274 | G10: =G9*(1+F10) -> 0.99134407 | H10: 0.022124184 | I10: =I9*(1+H10) -> 0.98027589 | J10: 0.038934573 | K10: 0.015383136 | L10: 0.044716352 | M10: 0.010803985 | N10: -0.00042523033 | O10: 0.057692308 | P10: -0.0016570816 | Q10: 0.018477517 | R10: 0.0035758185 | S10: 0.025641759 | T10: 0.0083640488 | U10: -0.0077811735 | V10: 0.016325028 | W10: 0.01612346 | X10: 0.0040639917 | Y10: 0.012832385 | Z10: 0
A11: 45972 | B11: 0.00026905942 | C11: =C10 * (1 + B11) -> 0.99194759 | D11: =MAX(D10,C11) -> 1 | E11: =(C11-D11)/D11 -> -0.0080524095 | F11: 0.0022892698 | G11: =G10*(1+F11) -> 0.99361352 | H11: -0.0026635432 | I11: =I10*(1+H11) -> 0.97766488 | J11: 0.0039574658 | K11: -0.16305274 | L11: -0.046795145 | M11: 0.0068017768 | N11: 0.015456608 | O11: -0.0060606061 | P11: 0.0099589924 | Q11: 0.0052964427 | R11: 0.021601158 | S11: -0.017941349 | T11: -0.0036552791 | U11: -0.0018567871 | V11: 0.0028180354 | W11: 0.027881673 | X11: 0.0037905557 | Y11: 0.0058777429 | Z11: 0
A12: 45973 | B12: -0.0040252753 | C12: =C11 * (1 + B12) -> 0.98795473 | D12: =MAX(D11,C12) -> 1 | E12: =(C12-D12)/D12 -> -0.012045272 | F12: 0.00055636896 | G12: =G11*(1+F12) -> 0.99416634 | H12: -0.00078832633 | I12: =I11*(1+H12) -> 0.97689416 | J12: -0.014773428 | K12: -0.033487951 | L12: -0.031722982 | M12: 0.013235902 | N12: -0.001396453 | O12: 0.0048780488 | P12: 0 | Q12: 0.0048360462 | R12: -0.0064668483 | S12: 0.0092624162 | T12: 0.025821927 | U12: 0.00015319633 | V12: -0.019670815 | W12: -0.01786305 | X12: -0.018689196 | Y12: -0.0077911959 | Z12: 0
A13: 45974 | B13: -0.015646205 | C13: =C12 * (1 + B13) -> 0.97249699 | D13: =MAX(D12,C13) -> 1 | E13: =(C13-D13)/D13 -> -0.027503014 | F13: -0.016593989 | G13: =G12*(1+F13) -> 0.97766915 | H13: -0.020416049 | I13: =I12*(1+H13) -> 0.95694984 | J13: -0.028911387 | K13: -0.082991923 | L13: -0.056122743 | M13: -0.0044904069 | N13: -0.0061529856 | O13: -0.0084951456 | P13: -0.0087006961 | Q13: -0.015357828 | R13: -0.0019014883 | S13: -0.04290299 | T13: -0.077854195 | U13: 0.012122538 | V13: -0.027108927 | W13: 0.0039294937 | X13: 0.014740412 | Y13: -0.0064127732 | Z13: 0
A14: 45975 | B14: 0.0014816958 | C14: =C13 * (1 + B14) -> 0.97393793 | D14: =MAX(D13,C14) -> 1 | E14: =(C14-D14)/D14 -> -0.026062069 | F14: -0.00016368073 | G14: =G13*(1+F14) -> 0.97750913 | H14: 0.00075608153 | I14: =I13*(1+H14) -> 0.95767337 | J14: -0.0076669533 | K14: -0.012509574 | L14: 0.044793449 | M14: -0.0082012028 | N14: 0.0012663571 | O14: -0.023255814 | P14: -0.00058513751 | Q14: 0.01368992 | R14: -0.0019783843 | S14: 0.0072945467 | T14: -0.015065632 | U14: -0.0022700739 | V14: -0.012164324 | W14: 0.021807202 | X14: 0.013112225 | Y14: -0.0021074816 | Z14: 0
... A251: 46322 | B251: 0.00054886722 | C251: =C250 * (1 + B251) -> 1.2040812 | D251: =MAX(D250,C251) -> 1.2369081 | E251: =(C251-D251)/D251 -> -0.026539444 | F251: 0.0056051322 | G251: =G250*(1+F251) -> 1.1196846 | H251: 0.012707105 | I251: =I250*(1+H251) -> 1.1344511 | J251: 0.008402559 | K251: 0.079362203 | L251: 0.043948343 | M251: -0.057011293 | N251: -0.01639698 | O251: 0.013259669 | P251: -0.0080638457 | Q251: -0.0023845287 | R251: 0.0092756826 | S251: 0.039979342 | T251: 0.020598089 | U251: -0.01296311 | V251: 0.016098599 | W251: -0.022527581 | X251: -0.016292401 | Y251: -0.0199233 | Z251: 0.011436351
